*** Starting uWSGI 2.0.17 (64bit) on [Wed May  2 16:20:01 2018] ***
compiled with version: 4.8.5 20150623 (Red Hat 4.8.5-16) on 24 April 2018 14:16:27
os: Linux-3.10.0-693.2.2.el7.x86_64 #1 SMP Tue Sep 12 22:26:13 UTC 2017
nodename: iZwz90t5fs54ubi0uwt7jjZ
machine: x86_64
clock source: unix
pcre jit disabled
detected number of CPU cores: 2
current working directory: /usr/local/workspace/git/mysite
writing pidfile to /usr/local/workspace/git/mysite/uwsgi.pid
detected binary path: /usr/bin/uwsgi
*** WARNING: you are running uWSGI as root !!! (use the --uid flag) *** 
chdir() to /usr/local/workspace/git/mysite/
your processes number limit is 15088
your memory page size is 4096 bytes
detected max file descriptor number: 65535
!!! no /etc/mime.types file found !!!
lock engine: pthread robust mutexes
thunder lock: enabled
uWSGI http bound on 127.0.0.1:8080 fd 3
uwsgi socket 0 bound to UNIX address /usr/local/workspace/git/mysite/uwsgi.sock fd 6
*** WARNING: you are running uWSGI as root !!! (use the --uid flag) *** 
Python version: 2.7.5 (default, Aug  4 2017, 00:39:18)  [GCC 4.8.5 20150623 (Red Hat 4.8.5-16)]
Python main interpreter initialized at 0x7e3e20
*** WARNING: you are running uWSGI as root !!! (use the --uid flag) *** 
python threads support enabled
your server socket listen backlog is limited to 100 connections
your mercy for graceful operations on workers is 60 seconds
mapped 486672 bytes (475 KB) for 5 cores
*** Operational MODE: preforking ***
Traceback (most recent call last):
  File "./mysite/wsgi.py", line 16, in <module>
    application = get_wsgi_application()
  File "/usr/lib64/python2.7/site-packages/django/core/wsgi.py", line 13, in get_wsgi_application
    django.setup(set_prefix=False)
  File "/usr/lib64/python2.7/site-packages/django/__init__.py", line 22, in setup
    configure_logging(settings.LOGGING_CONFIG, settings.LOGGING)
  File "/usr/lib64/python2.7/site-packages/django/conf/__init__.py", line 56, in __getattr__
    self._setup(name)
  File "/usr/lib64/python2.7/site-packages/django/conf/__init__.py", line 41, in _setup
    self._wrapped = Settings(settings_module)
  File "/usr/lib64/python2.7/site-packages/django/conf/__init__.py", line 110, in __init__
    mod = importlib.import_module(self.SETTINGS_MODULE)
  File "/usr/lib64/python2.7/importlib/__init__.py", line 37, in import_module
    __import__(name)
  File "./mysite/settings.py", line 125
SyntaxError: Non-ASCII character '\xe5' in file ./mysite/settings.py on line 125, but no encoding declared; see http://www.python.org/peps/pep-0263.html for details
unable to load app 0 (mountpoint='') (callable not found or import error)
*** no app loaded. going in full dynamic mode ***
*** WARNING: you are running uWSGI as root !!! (use the --uid flag) *** 
*** uWSGI is running in multiple interpreter mode ***
spawned uWSGI master process (pid: 11416)
spawned uWSGI worker 1 (pid: 11421, cores: 1)
spawned uWSGI worker 2 (pid: 11422, cores: 1)
spawned uWSGI worker 3 (pid: 11423, cores: 1)
spawned uWSGI worker 4 (pid: 11424, cores: 1)
spawned uWSGI worker 5 (pid: 11425, cores: 1)
spawned uWSGI http 1 (pid: 11426)
